2020-04-26 21:53:07,458 INFO: Flaskblog startup [in /Users/sridharvanaparthi/projects/flaskmegamig/flaskblog/myapp/__init__.py:43]
2020-04-26 21:54:12,137 ERROR: Exception on /edit_profile [POST] [in /Users/sridharvanaparthi/projects/flaskmegamig/flaskblog/venv/lib/python3.8/site-packages/flask/app.py:1891]
Traceback (most recent call last):
  File "/Users/sridharvanaparthi/projects/flaskmegamig/flaskblog/venv/lib/python3.8/site-packages/sqlalchemy/engine/base.py", line 1247, in _execute_context
    self.dialect.do_execute(
  File "/Users/sridharvanaparthi/projects/flaskmegamig/flaskblog/venv/lib/python3.8/site-packages/sqlalchemy/engine/default.py", line 590, in do_execute
    cursor.execute(statement, parameters)
sqlite3.IntegrityError: UNIQUE constraint failed: user.username

The above exception was the direct cause of the following exception:

Traceback (most recent call last):
  File "/Users/sridharvanaparthi/projects/flaskmegamig/flaskblog/venv/lib/python3.8/site-packages/flask/app.py", line 2447, in wsgi_app
    response = self.full_dispatch_request()
  File "/Users/sridharvanaparthi/projects/flaskmegamig/flaskblog/venv/lib/python3.8/site-packages/flask/app.py", line 1952, in full_dispatch_request
    rv = self.handle_user_exception(e)
  File "/Users/sridharvanaparthi/projects/flaskmegamig/flaskblog/venv/lib/python3.8/site-packages/flask/app.py", line 1821, in handle_user_exception
    reraise(exc_type, exc_value, tb)
  File "/Users/sridharvanaparthi/projects/flaskmegamig/flaskblog/venv/lib/python3.8/site-packages/flask/_compat.py", line 39, in reraise
    raise value
  File "/Users/sridharvanaparthi/projects/flaskmegamig/flaskblog/venv/lib/python3.8/site-packages/flask/app.py", line 1950, in full_dispatch_request
    rv = self.dispatch_request()
  File "/Users/sridharvanaparthi/projects/flaskmegamig/flaskblog/venv/lib/python3.8/site-packages/flask/app.py", line 1936, in dispatch_request
    return self.view_functions[rule.endpoint](**req.view_args)
  File "/Users/sridharvanaparthi/projects/flaskmegamig/flaskblog/venv/lib/python3.8/site-packages/flask_login/utils.py", line 272, in decorated_view
    return func(*args, **kwargs)
  File "/Users/sridharvanaparthi/projects/flaskmegamig/flaskblog/myapp/routes.py", line 86, in edit_profile
    db.session.commit()
  File "/Users/sridharvanaparthi/projects/flaskmegamig/flaskblog/venv/lib/python3.8/site-packages/sqlalchemy/orm/scoping.py", line 162, in do
    return getattr(self.registry(), name)(*args, **kwargs)
  File "/Users/sridharvanaparthi/projects/flaskmegamig/flaskblog/venv/lib/python3.8/site-packages/sqlalchemy/orm/session.py", line 1036, in commit
    self.transaction.commit()
  File "/Users/sridharvanaparthi/projects/flaskmegamig/flaskblog/venv/lib/python3.8/site-packages/sqlalchemy/orm/session.py", line 503, in commit
    self._prepare_impl()
  File "/Users/sridharvanaparthi/projects/flaskmegamig/flaskblog/venv/lib/python3.8/site-packages/sqlalchemy/orm/session.py", line 482, in _prepare_impl
    self.session.flush()
  File "/Users/sridharvanaparthi/projects/flaskmegamig/flaskblog/venv/lib/python3.8/site-packages/sqlalchemy/orm/session.py", line 2496, in flush
    self._flush(objects)
  File "/Users/sridharvanaparthi/projects/flaskmegamig/flaskblog/venv/lib/python3.8/site-packages/sqlalchemy/orm/session.py", line 2637, in _flush
    transaction.rollback(_capture_exception=True)
  File "/Users/sridharvanaparthi/projects/flaskmegamig/flaskblog/venv/lib/python3.8/site-packages/sqlalchemy/util/langhelpers.py", line 68, in __exit__
    compat.raise_(
  File "/Users/sridharvanaparthi/projects/flaskmegamig/flaskblog/venv/lib/python3.8/site-packages/sqlalchemy/util/compat.py", line 178, in raise_
    raise exception
  File "/Users/sridharvanaparthi/projects/flaskmegamig/flaskblog/venv/lib/python3.8/site-packages/sqlalchemy/orm/session.py", line 2597, in _flush
    flush_context.execute()
  File "/Users/sridharvanaparthi/projects/flaskmegamig/flaskblog/venv/lib/python3.8/site-packages/sqlalchemy/orm/unitofwork.py", line 422, in execute
    rec.execute(self)
  File "/Users/sridharvanaparthi/projects/flaskmegamig/flaskblog/venv/lib/python3.8/site-packages/sqlalchemy/orm/unitofwork.py", line 586, in execute
    persistence.save_obj(
  File "/Users/sridharvanaparthi/projects/flaskmegamig/flaskblog/venv/lib/python3.8/site-packages/sqlalchemy/orm/persistence.py", line 230, in save_obj
    _emit_update_statements(
  File "/Users/sridharvanaparthi/projects/flaskmegamig/flaskblog/venv/lib/python3.8/site-packages/sqlalchemy/orm/persistence.py", line 994, in _emit_update_statements
    c = cached_connections[connection].execute(
  File "/Users/sridharvanaparthi/projects/flaskmegamig/flaskblog/venv/lib/python3.8/site-packages/sqlalchemy/engine/base.py", line 984, in execute
    return meth(self, multiparams, params)
  File "/Users/sridharvanaparthi/projects/flaskmegamig/flaskblog/venv/lib/python3.8/site-packages/sqlalchemy/sql/elements.py", line 293, in _execute_on_connection
    return connection._execute_clauseelement(self, multiparams, params)
  File "/Users/sridharvanaparthi/projects/flaskmegamig/flaskblog/venv/lib/python3.8/site-packages/sqlalchemy/engine/base.py", line 1097, in _execute_clauseelement
    ret = self._execute_context(
  File "/Users/sridharvanaparthi/projects/flaskmegamig/flaskblog/venv/lib/python3.8/site-packages/sqlalchemy/engine/base.py", line 1287, in _execute_context
    self._handle_dbapi_exception(
  File "/Users/sridharvanaparthi/projects/flaskmegamig/flaskblog/venv/lib/python3.8/site-packages/sqlalchemy/engine/base.py", line 1481, in _handle_dbapi_exception
    util.raise_(
  File "/Users/sridharvanaparthi/projects/flaskmegamig/flaskblog/venv/lib/python3.8/site-packages/sqlalchemy/util/compat.py", line 178, in raise_
    raise exception
  File "/Users/sridharvanaparthi/projects/flaskmegamig/flaskblog/venv/lib/python3.8/site-packages/sqlalchemy/engine/base.py", line 1247, in _execute_context
    self.dialect.do_execute(
  File "/Users/sridharvanaparthi/projects/flaskmegamig/flaskblog/venv/lib/python3.8/site-packages/sqlalchemy/engine/default.py", line 590, in do_execute
    cursor.execute(statement, parameters)
sqlalchemy.exc.IntegrityError: (sqlite3.IntegrityError) UNIQUE constraint failed: user.username
[SQL: UPDATE user SET username=?, about_me=? WHERE user.id = ?]
[parameters: ('susan', 'This is about me for sridvana', 2)]
(Background on this error at: http://sqlalche.me/e/gkpj)
2020-04-26 22:00:28,239 INFO: Flaskblog startup [in /Users/sridharvanaparthi/projects/flaskmegamig/flaskblog/myapp/__init__.py:43]
2020-04-26 22:16:41,477 INFO: Flaskblog startup [in /Users/sridharvanaparthi/projects/flaskmegamig/flaskblog/myapp/__init__.py:43]
2020-04-26 22:18:39,017 INFO: Flaskblog startup [in /Users/sridharvanaparthi/projects/flaskmegamig/flaskblog/myapp/__init__.py:43]
2020-04-26 22:18:50,053 INFO: Flaskblog startup [in /Users/sridharvanaparthi/projects/flaskmegamig/flaskblog/myapp/__init__.py:43]
2020-04-26 22:21:23,584 INFO: Flaskblog startup [in /Users/sridharvanaparthi/projects/flaskmegamig/flaskblog/myapp/__init__.py:43]
2020-04-26 22:31:26,531 INFO: Flaskblog startup [in /Users/sridharvanaparthi/projects/flaskmegamig/flaskblog/myapp/__init__.py:43]
2020-04-26 22:45:10,393 INFO: Flaskblog startup [in /Users/sridharvanaparthi/projects/flaskmegamig/flaskblog/myapp/__init__.py:43]
2020-04-26 22:45:23,040 INFO: Flaskblog startup [in /Users/sridharvanaparthi/projects/flaskmegamig/flaskblog/myapp/__init__.py:43]
2020-04-26 23:04:29,553 INFO: Flaskblog startup [in /Users/sridharvanaparthi/projects/flaskmegamig/flaskblog/myapp/__init__.py:43]
2020-04-26 23:16:32,047 INFO: Flaskblog startup [in /Users/sridharvanaparthi/projects/flaskmegamig/flaskblog/myapp/__init__.py:43]
2020-04-26 23:16:41,058 ERROR: Exception on /index [GET] [in /Users/sridharvanaparthi/projects/flaskmegamig/flaskblog/venv/lib/python3.8/site-packages/flask/app.py:1891]
Traceback (most recent call last):
  File "/Users/sridharvanaparthi/projects/flaskmegamig/flaskblog/venv/lib/python3.8/site-packages/flask/app.py", line 2447, in wsgi_app
    response = self.full_dispatch_request()
  File "/Users/sridharvanaparthi/projects/flaskmegamig/flaskblog/venv/lib/python3.8/site-packages/flask/app.py", line 1952, in full_dispatch_request
    rv = self.handle_user_exception(e)
  File "/Users/sridharvanaparthi/projects/flaskmegamig/flaskblog/venv/lib/python3.8/site-packages/flask/app.py", line 1821, in handle_user_exception
    reraise(exc_type, exc_value, tb)
  File "/Users/sridharvanaparthi/projects/flaskmegamig/flaskblog/venv/lib/python3.8/site-packages/flask/_compat.py", line 39, in reraise
    raise value
  File "/Users/sridharvanaparthi/projects/flaskmegamig/flaskblog/venv/lib/python3.8/site-packages/flask/app.py", line 1950, in full_dispatch_request
    rv = self.dispatch_request()
  File "/Users/sridharvanaparthi/projects/flaskmegamig/flaskblog/venv/lib/python3.8/site-packages/flask/app.py", line 1936, in dispatch_request
    return self.view_functions[rule.endpoint](**req.view_args)
  File "/Users/sridharvanaparthi/projects/flaskmegamig/flaskblog/venv/lib/python3.8/site-packages/flask_login/utils.py", line 272, in decorated_view
    return func(*args, **kwargs)
  File "/Users/sridharvanaparthi/projects/flaskmegamig/flaskblog/myapp/routes.py", line 28, in index
    page, app.config['POSTS_PER_PAGE'], False)
KeyError: 'POSTS_PER_PAGE'
2020-04-26 23:22:42,803 INFO: Flaskblog startup [in /Users/sridharvanaparthi/projects/flaskmegamig/flaskblog/myapp/__init__.py:43]
